2022-02-04 16:24:04,034 ERROR: Exception on /index [GET] [in /home/gauti/microblog/venv/lib/python3.8/site-packages/flask/app.py:1457]
Traceback (most recent call last):
  File "/home/gauti/microblog/venv/lib/python3.8/site-packages/flask/app.py", line 2073, in wsgi_app
    response = self.full_dispatch_request()
  File "/home/gauti/microblog/venv/lib/python3.8/site-packages/flask/app.py", line 1518, in full_dispatch_request
    rv = self.handle_user_exception(e)
  File "/home/gauti/microblog/venv/lib/python3.8/site-packages/flask/app.py", line 1516, in full_dispatch_request
    rv = self.dispatch_request()
  File "/home/gauti/microblog/venv/lib/python3.8/site-packages/flask/app.py", line 1502, in dispatch_request
    return self.ensure_sync(self.view_functions[rule.endpoint])(**req.view_args)
  File "/home/gauti/microblog/venv/lib/python3.8/site-packages/flask_login/utils.py", line 272, in decorated_view
    return func(*args, **kwargs)
  File "/home/gauti/microblog/venv/app/routes.py", line 21, in index
    page = request.args.get('page', 1, type = 'int')
  File "/home/gauti/microblog/venv/lib/python3.8/site-packages/werkzeug/datastructures.py", line 267, in get
    rv = type(rv)
TypeError: 'str' object is not callable
2022-02-04 16:24:09,058 ERROR: Exception on /index [GET] [in /home/gauti/microblog/venv/lib/python3.8/site-packages/flask/app.py:1457]
Traceback (most recent call last):
  File "/home/gauti/microblog/venv/lib/python3.8/site-packages/flask/app.py", line 2073, in wsgi_app
    response = self.full_dispatch_request()
  File "/home/gauti/microblog/venv/lib/python3.8/site-packages/flask/app.py", line 1518, in full_dispatch_request
    rv = self.handle_user_exception(e)
  File "/home/gauti/microblog/venv/lib/python3.8/site-packages/flask/app.py", line 1516, in full_dispatch_request
    rv = self.dispatch_request()
  File "/home/gauti/microblog/venv/lib/python3.8/site-packages/flask/app.py", line 1502, in dispatch_request
    return self.ensure_sync(self.view_functions[rule.endpoint])(**req.view_args)
  File "/home/gauti/microblog/venv/lib/python3.8/site-packages/flask_login/utils.py", line 272, in decorated_view
    return func(*args, **kwargs)
  File "/home/gauti/microblog/venv/app/routes.py", line 21, in index
    page = request.args.get('page', 1, type = 'int')
  File "/home/gauti/microblog/venv/lib/python3.8/site-packages/werkzeug/datastructures.py", line 267, in get
    rv = type(rv)
TypeError: 'str' object is not callable
2022-02-04 16:26:12,423 ERROR: Exception on /index [GET] [in /home/gauti/microblog/venv/lib/python3.8/site-packages/flask/app.py:1457]
Traceback (most recent call last):
  File "/home/gauti/microblog/venv/lib/python3.8/site-packages/flask/app.py", line 2073, in wsgi_app
    response = self.full_dispatch_request()
  File "/home/gauti/microblog/venv/lib/python3.8/site-packages/flask/app.py", line 1518, in full_dispatch_request
    rv = self.handle_user_exception(e)
  File "/home/gauti/microblog/venv/lib/python3.8/site-packages/flask/app.py", line 1516, in full_dispatch_request
    rv = self.dispatch_request()
  File "/home/gauti/microblog/venv/lib/python3.8/site-packages/flask/app.py", line 1502, in dispatch_request
    return self.ensure_sync(self.view_functions[rule.endpoint])(**req.view_args)
  File "/home/gauti/microblog/venv/lib/python3.8/site-packages/flask_login/utils.py", line 272, in decorated_view
    return func(*args, **kwargs)
  File "/home/gauti/microblog/venv/app/routes.py", line 21, in index
    page = request.args.get('page', 1, type = 'int')
  File "/home/gauti/microblog/venv/lib/python3.8/site-packages/werkzeug/datastructures.py", line 267, in get
    rv = type(rv)
TypeError: 'str' object is not callable
2022-02-04 16:27:35,752 INFO: Microblog startup [in /home/gauti/microblog/venv/app/__init__.py:45]
